2024-10-03 18:35:29 -  HTTP Error 404: Not Found
Traceback (most recent call last):
  File "c:\Users\vitor\Desktop\mini_mercado\api.py", line 22, in get_product_data_from_cosmos_by_ean
    with urllib.request.urlopen(req, context=context) as response:
         ^^^^^^^^^^^^^^^^^^^^^^^^^^^^^^^^^^^^^^^^^^^^
  File "C:\Users\vitor\AppData\Local\Programs\Python\Python312\Lib\urllib\request.py", line 215, in urlopen
    return opener.open(url, data, timeout)
           ^^^^^^^^^^^^^^^^^^^^^^^^^^^^^^^
  File "C:\Users\vitor\AppData\Local\Programs\Python\Python312\Lib\urllib\request.py", line 521, in open
    response = meth(req, response)
               ^^^^^^^^^^^^^^^^^^^
  File "C:\Users\vitor\AppData\Local\Programs\Python\Python312\Lib\urllib\request.py", line 630, in http_response
    response = self.parent.error(
               ^^^^^^^^^^^^^^^^^^
  File "C:\Users\vitor\AppData\Local\Programs\Python\Python312\Lib\urllib\request.py", line 559, in error
    return self._call_chain(*args)
           ^^^^^^^^^^^^^^^^^^^^^^^
  File "C:\Users\vitor\AppData\Local\Programs\Python\Python312\Lib\urllib\request.py", line 492, in _call_chain
    result = func(*args)
             ^^^^^^^^^^^
  File "C:\Users\vitor\AppData\Local\Programs\Python\Python312\Lib\urllib\request.py", line 639, in http_error_default
    raise HTTPError(req.full_url, code, msg, hdrs, fp)
urllib.error.HTTPError: HTTP Error 404: Not Found

---
